{
 "cells": [
  {
   "cell_type": "code",
   "execution_count": 8,
   "metadata": {},
   "outputs": [
    {
     "name": "stdout",
     "output_type": "stream",
     "text": [
      "Starting training...\n",
      "Epoch 1/5\n"
     ]
    },
    {
     "name": "stderr",
     "output_type": "stream",
     "text": [
      "/home/gino/miniconda3/envs/tf/lib/python3.10/site-packages/keras/src/layers/reshaping/flatten.py:37: UserWarning: Do not pass an `input_shape`/`input_dim` argument to a layer. When using Sequential models, prefer using an `Input(shape)` object as the first layer in the model instead.\n",
      "  super().__init__(**kwargs)\n",
      "WARNING: All log messages before absl::InitializeLog() is called are written to STDERR\n",
      "I0000 00:00:1731372822.903724   12091 service.cc:146] XLA service 0x78583c008fd0 initialized for platform CUDA (this does not guarantee that XLA will be used). Devices:\n",
      "I0000 00:00:1731372822.903737   12091 service.cc:154]   StreamExecutor device (0): NVIDIA GeForce RTX 4090, Compute Capability 8.9\n",
      "2024-11-11 18:53:42.912397: I tensorflow/compiler/mlir/tensorflow/utils/dump_mlir_util.cc:268] disabling MLIR crash reproducer, set env var `MLIR_CRASH_REPRODUCER_DIRECTORY` to enable.\n",
      "2024-11-11 18:53:43.245352: E external/local_xla/xla/stream_executor/cuda/cuda_dnn.cc:524] Loaded runtime CuDNN library: 8.2.1 but source was compiled with: 8.9.6.  CuDNN library needs to have matching major version and equal or higher minor version. If using a binary install, upgrade your CuDNN library.  If building from sources, make sure the library loaded at runtime is compatible with the version specified during compile configuration.\n",
      "2024-11-11 18:53:43.250044: E external/local_xla/xla/stream_executor/cuda/cuda_dnn.cc:524] Loaded runtime CuDNN library: 8.2.1 but source was compiled with: 8.9.6.  CuDNN library needs to have matching major version and equal or higher minor version. If using a binary install, upgrade your CuDNN library.  If building from sources, make sure the library loaded at runtime is compatible with the version specified during compile configuration.\n",
      "2024-11-11 18:53:43.252239: W tensorflow/core/framework/op_kernel.cc:1840] OP_REQUIRES failed at xla_ops.cc:577 : FAILED_PRECONDITION: DNN library initialization failed. Look at the errors above for more details.\n",
      "2024-11-11 18:53:43.252258: I tensorflow/core/framework/local_rendezvous.cc:404] Local rendezvous is aborting with status: FAILED_PRECONDITION: DNN library initialization failed. Look at the errors above for more details.\n",
      "\t [[{{node StatefulPartitionedCall}}]]\n"
     ]
    },
    {
     "ename": "FailedPreconditionError",
     "evalue": "Graph execution error:\n\nDetected at node StatefulPartitionedCall defined at (most recent call last):\n  File \"/home/gino/miniconda3/envs/tf/lib/python3.10/runpy.py\", line 196, in _run_module_as_main\n\n  File \"/home/gino/miniconda3/envs/tf/lib/python3.10/runpy.py\", line 86, in _run_code\n\n  File \"/home/gino/.local/lib/python3.10/site-packages/ipykernel_launcher.py\", line 17, in <module>\n\n  File \"/home/gino/.local/lib/python3.10/site-packages/traitlets/config/application.py\", line 1077, in launch_instance\n\n  File \"/home/gino/.local/lib/python3.10/site-packages/ipykernel/kernelapp.py\", line 739, in start\n\n  File \"/home/gino/.local/lib/python3.10/site-packages/tornado/platform/asyncio.py\", line 205, in start\n\n  File \"/home/gino/miniconda3/envs/tf/lib/python3.10/asyncio/base_events.py\", line 603, in run_forever\n\n  File \"/home/gino/miniconda3/envs/tf/lib/python3.10/asyncio/base_events.py\", line 1909, in _run_once\n\n  File \"/home/gino/miniconda3/envs/tf/lib/python3.10/asyncio/events.py\", line 80, in _run\n\n  File \"/home/gino/.local/lib/python3.10/site-packages/ipykernel/kernelbase.py\", line 529, in dispatch_queue\n\n  File \"/home/gino/.local/lib/python3.10/site-packages/ipykernel/kernelbase.py\", line 518, in process_one\n\n  File \"/home/gino/.local/lib/python3.10/site-packages/ipykernel/kernelbase.py\", line 424, in dispatch_shell\n\n  File \"/home/gino/.local/lib/python3.10/site-packages/ipykernel/kernelbase.py\", line 766, in execute_request\n\n  File \"/home/gino/.local/lib/python3.10/site-packages/ipykernel/ipkernel.py\", line 429, in do_execute\n\n  File \"/home/gino/.local/lib/python3.10/site-packages/ipykernel/zmqshell.py\", line 549, in run_cell\n\n  File \"/home/gino/.local/lib/python3.10/site-packages/IPython/core/interactiveshell.py\", line 3048, in run_cell\n\n  File \"/home/gino/.local/lib/python3.10/site-packages/IPython/core/interactiveshell.py\", line 3103, in _run_cell\n\n  File \"/home/gino/.local/lib/python3.10/site-packages/IPython/core/async_helpers.py\", line 129, in _pseudo_sync_runner\n\n  File \"/home/gino/.local/lib/python3.10/site-packages/IPython/core/interactiveshell.py\", line 3308, in run_cell_async\n\n  File \"/home/gino/.local/lib/python3.10/site-packages/IPython/core/interactiveshell.py\", line 3490, in run_ast_nodes\n\n  File \"/home/gino/.local/lib/python3.10/site-packages/IPython/core/interactiveshell.py\", line 3550, in run_code\n\n  File \"/tmp/ipykernel_11932/2632096921.py\", line 25, in <module>\n\n  File \"/home/gino/miniconda3/envs/tf/lib/python3.10/site-packages/keras/src/utils/traceback_utils.py\", line 117, in error_handler\n\n  File \"/home/gino/miniconda3/envs/tf/lib/python3.10/site-packages/keras/src/backend/tensorflow/trainer.py\", line 320, in fit\n\n  File \"/home/gino/miniconda3/envs/tf/lib/python3.10/site-packages/keras/src/backend/tensorflow/trainer.py\", line 121, in one_step_on_iterator\n\nDNN library initialization failed. Look at the errors above for more details.\n\t [[{{node StatefulPartitionedCall}}]] [Op:__inference_one_step_on_iterator_1567]",
     "output_type": "error",
     "traceback": [
      "\u001b[0;31m---------------------------------------------------------------------------\u001b[0m",
      "\u001b[0;31mFailedPreconditionError\u001b[0m                   Traceback (most recent call last)",
      "Cell \u001b[0;32mIn[8], line 25\u001b[0m\n\u001b[1;32m     23\u001b[0m \u001b[38;5;66;03m# Train the model\u001b[39;00m\n\u001b[1;32m     24\u001b[0m \u001b[38;5;28mprint\u001b[39m(\u001b[38;5;124m\"\u001b[39m\u001b[38;5;124mStarting training...\u001b[39m\u001b[38;5;124m\"\u001b[39m)\n\u001b[0;32m---> 25\u001b[0m history \u001b[38;5;241m=\u001b[39m \u001b[43mmodel\u001b[49m\u001b[38;5;241;43m.\u001b[39;49m\u001b[43mfit\u001b[49m\u001b[43m(\u001b[49m\u001b[43mX_train\u001b[49m\u001b[43m,\u001b[49m\u001b[43m \u001b[49m\u001b[43my_train\u001b[49m\u001b[43m,\u001b[49m\u001b[43m \u001b[49m\u001b[43mepochs\u001b[49m\u001b[38;5;241;43m=\u001b[39;49m\u001b[38;5;241;43m5\u001b[39;49m\u001b[43m,\u001b[49m\u001b[43m \u001b[49m\u001b[43mbatch_size\u001b[49m\u001b[38;5;241;43m=\u001b[39;49m\u001b[38;5;241;43m64\u001b[39;49m\u001b[43m,\u001b[49m\u001b[43m \u001b[49m\u001b[43mvalidation_data\u001b[49m\u001b[38;5;241;43m=\u001b[39;49m\u001b[43m(\u001b[49m\u001b[43mX_test\u001b[49m\u001b[43m,\u001b[49m\u001b[43m \u001b[49m\u001b[43my_test\u001b[49m\u001b[43m)\u001b[49m\u001b[43m)\u001b[49m\n\u001b[1;32m     27\u001b[0m \u001b[38;5;66;03m# Evaluate the model\u001b[39;00m\n\u001b[1;32m     28\u001b[0m \u001b[38;5;28mprint\u001b[39m(\u001b[38;5;124m\"\u001b[39m\u001b[38;5;124mEvaluating model...\u001b[39m\u001b[38;5;124m\"\u001b[39m)\n",
      "File \u001b[0;32m~/miniconda3/envs/tf/lib/python3.10/site-packages/keras/src/utils/traceback_utils.py:122\u001b[0m, in \u001b[0;36mfilter_traceback.<locals>.error_handler\u001b[0;34m(*args, **kwargs)\u001b[0m\n\u001b[1;32m    119\u001b[0m     filtered_tb \u001b[38;5;241m=\u001b[39m _process_traceback_frames(e\u001b[38;5;241m.\u001b[39m__traceback__)\n\u001b[1;32m    120\u001b[0m     \u001b[38;5;66;03m# To get the full stack trace, call:\u001b[39;00m\n\u001b[1;32m    121\u001b[0m     \u001b[38;5;66;03m# `keras.config.disable_traceback_filtering()`\u001b[39;00m\n\u001b[0;32m--> 122\u001b[0m     \u001b[38;5;28;01mraise\u001b[39;00m e\u001b[38;5;241m.\u001b[39mwith_traceback(filtered_tb) \u001b[38;5;28;01mfrom\u001b[39;00m \u001b[38;5;28;01mNone\u001b[39;00m\n\u001b[1;32m    123\u001b[0m \u001b[38;5;28;01mfinally\u001b[39;00m:\n\u001b[1;32m    124\u001b[0m     \u001b[38;5;28;01mdel\u001b[39;00m filtered_tb\n",
      "File \u001b[0;32m~/.local/lib/python3.10/site-packages/tensorflow/python/eager/execute.py:53\u001b[0m, in \u001b[0;36mquick_execute\u001b[0;34m(op_name, num_outputs, inputs, attrs, ctx, name)\u001b[0m\n\u001b[1;32m     51\u001b[0m \u001b[38;5;28;01mtry\u001b[39;00m:\n\u001b[1;32m     52\u001b[0m   ctx\u001b[38;5;241m.\u001b[39mensure_initialized()\n\u001b[0;32m---> 53\u001b[0m   tensors \u001b[38;5;241m=\u001b[39m pywrap_tfe\u001b[38;5;241m.\u001b[39mTFE_Py_Execute(ctx\u001b[38;5;241m.\u001b[39m_handle, device_name, op_name,\n\u001b[1;32m     54\u001b[0m                                       inputs, attrs, num_outputs)\n\u001b[1;32m     55\u001b[0m \u001b[38;5;28;01mexcept\u001b[39;00m core\u001b[38;5;241m.\u001b[39m_NotOkStatusException \u001b[38;5;28;01mas\u001b[39;00m e:\n\u001b[1;32m     56\u001b[0m   \u001b[38;5;28;01mif\u001b[39;00m name \u001b[38;5;129;01mis\u001b[39;00m \u001b[38;5;129;01mnot\u001b[39;00m \u001b[38;5;28;01mNone\u001b[39;00m:\n",
      "\u001b[0;31mFailedPreconditionError\u001b[0m: Graph execution error:\n\nDetected at node StatefulPartitionedCall defined at (most recent call last):\n  File \"/home/gino/miniconda3/envs/tf/lib/python3.10/runpy.py\", line 196, in _run_module_as_main\n\n  File \"/home/gino/miniconda3/envs/tf/lib/python3.10/runpy.py\", line 86, in _run_code\n\n  File \"/home/gino/.local/lib/python3.10/site-packages/ipykernel_launcher.py\", line 17, in <module>\n\n  File \"/home/gino/.local/lib/python3.10/site-packages/traitlets/config/application.py\", line 1077, in launch_instance\n\n  File \"/home/gino/.local/lib/python3.10/site-packages/ipykernel/kernelapp.py\", line 739, in start\n\n  File \"/home/gino/.local/lib/python3.10/site-packages/tornado/platform/asyncio.py\", line 205, in start\n\n  File \"/home/gino/miniconda3/envs/tf/lib/python3.10/asyncio/base_events.py\", line 603, in run_forever\n\n  File \"/home/gino/miniconda3/envs/tf/lib/python3.10/asyncio/base_events.py\", line 1909, in _run_once\n\n  File \"/home/gino/miniconda3/envs/tf/lib/python3.10/asyncio/events.py\", line 80, in _run\n\n  File \"/home/gino/.local/lib/python3.10/site-packages/ipykernel/kernelbase.py\", line 529, in dispatch_queue\n\n  File \"/home/gino/.local/lib/python3.10/site-packages/ipykernel/kernelbase.py\", line 518, in process_one\n\n  File \"/home/gino/.local/lib/python3.10/site-packages/ipykernel/kernelbase.py\", line 424, in dispatch_shell\n\n  File \"/home/gino/.local/lib/python3.10/site-packages/ipykernel/kernelbase.py\", line 766, in execute_request\n\n  File \"/home/gino/.local/lib/python3.10/site-packages/ipykernel/ipkernel.py\", line 429, in do_execute\n\n  File \"/home/gino/.local/lib/python3.10/site-packages/ipykernel/zmqshell.py\", line 549, in run_cell\n\n  File \"/home/gino/.local/lib/python3.10/site-packages/IPython/core/interactiveshell.py\", line 3048, in run_cell\n\n  File \"/home/gino/.local/lib/python3.10/site-packages/IPython/core/interactiveshell.py\", line 3103, in _run_cell\n\n  File \"/home/gino/.local/lib/python3.10/site-packages/IPython/core/async_helpers.py\", line 129, in _pseudo_sync_runner\n\n  File \"/home/gino/.local/lib/python3.10/site-packages/IPython/core/interactiveshell.py\", line 3308, in run_cell_async\n\n  File \"/home/gino/.local/lib/python3.10/site-packages/IPython/core/interactiveshell.py\", line 3490, in run_ast_nodes\n\n  File \"/home/gino/.local/lib/python3.10/site-packages/IPython/core/interactiveshell.py\", line 3550, in run_code\n\n  File \"/tmp/ipykernel_11932/2632096921.py\", line 25, in <module>\n\n  File \"/home/gino/miniconda3/envs/tf/lib/python3.10/site-packages/keras/src/utils/traceback_utils.py\", line 117, in error_handler\n\n  File \"/home/gino/miniconda3/envs/tf/lib/python3.10/site-packages/keras/src/backend/tensorflow/trainer.py\", line 320, in fit\n\n  File \"/home/gino/miniconda3/envs/tf/lib/python3.10/site-packages/keras/src/backend/tensorflow/trainer.py\", line 121, in one_step_on_iterator\n\nDNN library initialization failed. Look at the errors above for more details.\n\t [[{{node StatefulPartitionedCall}}]] [Op:__inference_one_step_on_iterator_1567]"
     ]
    }
   ],
   "source": [
    "import tensorflow as tf\n",
    "from tensorflow.keras.models import Sequential\n",
    "from tensorflow.keras.layers import Dense, Flatten\n",
    "from tensorflow.keras.datasets import mnist\n",
    "\n",
    "# Load the MNIST dataset\n",
    "(X_train, y_train), (X_test, y_test) = mnist.load_data()\n",
    "X_train, X_test = X_train / 255.0, X_test / 255.0  # Normalize pixel values\n",
    "\n",
    "# Define a simple model\n",
    "model = Sequential([\n",
    "    Flatten(input_shape=(28, 28)),  # Flatten the 28x28 images\n",
    "    Dense(128, activation='relu'),\n",
    "    Dense(64, activation='relu'),\n",
    "    Dense(10, activation='softmax')  # Output layer for 10 classes\n",
    "])\n",
    "\n",
    "# Compile the model\n",
    "model.compile(optimizer='adam',\n",
    "              loss='sparse_categorical_crossentropy',\n",
    "              metrics=['accuracy'])\n",
    "\n",
    "# Train the model\n",
    "print(\"Starting training...\")\n",
    "history = model.fit(X_train, y_train, epochs=5, batch_size=64, validation_data=(X_test, y_test))\n",
    "\n",
    "# Evaluate the model\n",
    "print(\"Evaluating model...\")\n",
    "test_loss, test_acc = model.evaluate(X_test, y_test)\n",
    "print(f\"Test accuracy: {test_acc}\")\n"
   ]
  }
 ],
 "metadata": {
  "kernelspec": {
   "display_name": "tf",
   "language": "python",
   "name": "tf"
  },
  "language_info": {
   "codemirror_mode": {
    "name": "ipython",
    "version": 3
   },
   "file_extension": ".py",
   "mimetype": "text/x-python",
   "name": "python",
   "nbconvert_exporter": "python",
   "pygments_lexer": "ipython3",
   "version": "3.10.14"
  }
 },
 "nbformat": 4,
 "nbformat_minor": 2
}
